<?xml version="1.0" encoding="utf-8"?>
<mujoco model="biped">

	<!-- Simulation Parameters -->
	<option timestep="0.001" iterations="15" ls_iterations="15" solver="Newton" gravity="0 0 -9.81">
		<flag eulerdamp="disable"/>
	</option>

	<!-- Specify the light settings -->
	<visual>
		<headlight diffuse="0.6 0.6 0.6" ambient="0.3 0.3 0.3" specular="0 0 0"/>
		<rgba haze="0.15 0.25 0.35 1"/>
		<global azimuth="150" elevation="-20" offwidth="720" offheight="480"/>
	</visual>

	<!-- Ground plane -->
	<asset>
        <texture type="skybox" builtin="gradient" rgb1="0.3 0.5 0.7" rgb2="0 0 0" width="512" height="3072"/>
        <texture type="2d" name="groundplane" builtin="checker" mark="edge" rgb1="0.2 0.3 0.4" rgb2="0.1 0.2 0.3"
        markrgb="0.8 0.8 0.8" width="300" height="300"/>
        <material name="groundplane" texture="groundplane" texuniform="true" texrepeat="1 1" reflectance="0.5"/> <!-- smallest checker square is 1 meter big-->
    </asset>  

	<!-- Set angles to be in radians -->
	<compiler angle="radian" autolimits="true" eulerseq="zyx"/>

    <!-- Default properties -->
	<default>
		<geom conaffinity="0" contype="0" density="100" friction="0.8 0.8 0.8"/>
		<default class="visual">
			<geom conaffinity="0" contype="0"/>
		</default>
	</default>

	<!-- Bodies -->
	<worldbody>
		<!-- Ground -->
		<geom name="plane" type="plane" size="0.0 0.0 0.125" material="groundplane"  conaffinity="1" contype="1"/>

		<!-- Origin Visual -->
		<geom name="origin_sphere" type="sphere" size="0.025" pos="0 0 0" rgba="1 0 0 1" conaffinity="0" contype="0"/>

		<!-- Robot -->
		<body name="torso" pos="0 0 0.0">

			<!-- A light that tracks the CoM -->
			<light pos="0 0 3" dir="0 0 -1" directional="false" mode="trackcom"/>

			<!-- torso -->
			<geom name="torso" type="capsule" size="0.075 0.4" pos="0 0 0.4" rgba="1.0 0.424 0.047 1.0" conaffinity="1" contype="1" density="500"/>
			<joint name="root_x" type="slide" axis="1  0 0"/>  <!-- Floating Base  x pos-->
			<joint name="root_z" type="slide" axis="0  0 1"/>  <!-- Floating Base  z pos-->
			<joint name="root_y" type="hinge" axis="0 -1 0"/>  <!-- Floating Base  y angle-->

				<!-- left thigh -->
				<body name="thigh_left" pos="0 0.1 0.0">
					<geom name="thigh_left" type="capsule" size="0.075 0.25" pos="0 0 -0.25" rgba="1.0 0.424 0.047 1.0" conaffinity="1" contype="1" density="100"/>
					<joint name="hip_left" axis="0 -1 0" pos="0 0 0.0" limited="true" range="-2.0 2.0"/>

					<!-- left shin -->
					<body name="shin_left" pos="0 0 -0.5">
						<geom name="shin_left" type="capsule" size="0.075 0.25" pos="0 0 -0.25" rgba="1.0 0.424 0.047 1.0" conaffinity="1" contype="1"  density="100"/>
						<joint name="knee_left" axis="0 -1 0" pos="0 0 0.0" limited="true" range="-2.0 0"/>
					</body>
				</body>

				<!-- right thigh -->
				<body name="thigh_right" pos="0 -0.1 0.0">
					<geom name="thigh_right" type="capsule" size="0.075 0.25" pos="0 0 -0.25" rgba="1.0 0.424 0.047 1.0" conaffinity="1" contype="1"  density="100"/>
					<joint name="hip_right" axis="0 -1 0" pos="0 0 0.0" limited="true" range="-2.0 2.0"/>

					<!-- right shin -->
					<body name="shin_right" pos="0 0 -0.5">
						<geom name="shin_right" type="capsule" size="0.075 0.25" pos="0 0 -0.25" rgba="1.0 0.424 0.047 1.0" conaffinity="1" contype="1"  density="100"/>
						<joint name="knee_right" axis="0 -1 0" pos="0 0 0.0" limited="true" range="-2.0 0"/>
					</body>
				</body>

		</body>

	</worldbody>

	<!-- actuators -->
	<actuator>
		<motor name="thigh_left_motor" joint="hip_left" ctrllimited="false" gear="1"/>
    	<motor name="shin_left_motor" joint="knee_left" ctrllimited="false" gear="1"/>
		<motor name="thigh_right_motor" joint="hip_right" ctrllimited="false" gear="1"/>
		<motor name="shin_right_motor" joint="knee_right" ctrllimited="false" gear="1"/>
	</actuator>

</mujoco>
